Workbook

Sheet Builder
A1: Builder Instructions | B1: 1) Fill inputs in column C. 2) For skills, pick skill name in C and value in D (20 rows). 3) For spells, pick spell names in the 20 spell rows. 4) Copy the generated block from the Output sheet into npcdesc.cfg. | H1: NpcTemplate Output
A2: HP Guidance | B2: STR is the base strength stat. CProp.BaseStrmod is an extra strength modifier applied by shard setup scripts after spawn. If HITS is filled, npcdesc can set a direct HP value from that field. If HITS is blank and CustomHitsLevel is not set, HP commonly follows the strength-based path, so STR plus BaseStrmod usually drives final max HP. If CProp.CustomHitsLevel exists, shard scripts treat it as the HP override and commonly read it in hundredths, so i30000 behaves like 300 HP. Use HITS for fixed HP, use STR plus BaseStrmod for stat-driven HP, and use CustomHitsLevel when you want an explicit override. | H2: ="NpcTemplate "&SUBSTITUTE(TRIM(C7)," ","") -> NpcTemplate
A3: Template Id | B3: NpcTemplateID is the first row under Identity. Keep it short and do not include spaces. | H3: {
H4: =IF($G7="","",$G7)
H5: =IF($G8="","",$G8)
A6: Group | B6: Key | C6: Value | D6: Skill Value | E6: What It Does | F6: Example | G6: Output Line | H6: =IF($G9="","",$G9)
A7: Identity | B7: NpcTemplateID | E7: Builder-only template id written after NpcTemplate. Use letters/numbers and no spaces. | F7: etherealhorse | G7: =IF(OR(B7="NpcTemplateID",C7=""),"",IF(B7="spell"," spell"&REPT(" ",MAX(1,24-LEN("spell")))&C7,IF(LEFT(B7,6)="CProp."," CProp"&REPT(" ",MAX(1,24-LEN("CProp")))&MID(B7,7,200)&REPT(" ",MAX(1,24-LEN(MID(B7,7,200))))&C7," "&B7&REPT(" ",MAX(1,24-LEN(B7)))&C7))) | H7: =IF($G10="","",$G10)
A8: Identity | B8: Name | E8: Display name for NPC; can use <random> tokens where supported. | F8: a dragon | G8: =IF(OR(B8="NpcTemplateID",C8=""),"",IF(B8="spell"," spell"&REPT(" ",MAX(1,24-LEN("spell")))&C8,IF(LEFT(B8,6)="CProp."," CProp"&REPT(" ",MAX(1,24-LEN("CProp")))&MID(B8,7,200)&REPT(" ",MAX(1,24-LEN(MID(B8,7,200))))&C8," "&B8&REPT(" ",MAX(1,24-LEN(B8)))&C8))) | H8: =IF($G11="","",$G11)
A9: Identity | B9: script | E9: AI/behavior script attached to NPC. | F9: killpcs | G9: =IF(OR(B9="NpcTemplateID",C9=""),"",IF(B9="spell"," spell"&REPT(" ",MAX(1,24-LEN("spell")))&C9,IF(LEFT(B9,6)="CProp."," CProp"&REPT(" ",MAX(1,24-LEN("CProp")))&MID(B9,7,200)&REPT(" ",MAX(1,24-LEN(MID(B9,7,200))))&C9," "&B9&REPT(" ",MAX(1,24-LEN(B9)))&C9))) | H9: =IF($G12="","",$G12)
A10: Identity | B10: objtype | E10: Body/object type ID (hex or decimal). | F10: 0x3b | G10: =IF(OR(B10="NpcTemplateID",C10=""),"",IF(B10="spell"," spell"&REPT(" ",MAX(1,24-LEN("spell")))&C10,IF(LEFT(B10,6)="CProp."," CProp"&REPT(" ",MAX(1,24-LEN("CProp")))&MID(B10,7,200)&REPT(" ",MAX(1,24-LEN(MID(B10,7,200))))&C10," "&B10&REPT(" ",MAX(1,24-LEN(B10)))&C10))) | H10: =IF($G13="","",$G13)
A11: Identity | B11: Color | E11: Hue override for body/equipment visuals. | F11: 0 | G11: =IF(OR(B11="NpcTemplateID",C11=""),"",IF(B11="spell"," spell"&REPT(" ",MAX(1,24-LEN("spell")))&C11,IF(LEFT(B11,6)="CProp."," CProp"&REPT(" ",MAX(1,24-LEN("CProp")))&MID(B11,7,200)&REPT(" ",MAX(1,24-LEN(MID(B11,7,200))))&C11," "&B11&REPT(" ",MAX(1,24-LEN(B11)))&C11))) | H11: =IF($G14="","",$G14)
A12: Identity | B12: TrueColor | E12: Permanent hue that should persist through updates. | F12: 0 | G12: =IF(OR(B12="NpcTemplateID",C12=""),"",IF(B12="spell"," spell"&REPT(" ",MAX(1,24-LEN("spell")))&C12,IF(LEFT(B12,6)="CProp."," CProp"&REPT(" ",MAX(1,24-LEN("CProp")))&MID(B12,7,200)&REPT(" ",MAX(1,24-LEN(MID(B12,7,200))))&C12," "&B12&REPT(" ",MAX(1,24-LEN(B12)))&C12))) | H12: =IF($G15="","",$G15)
A13: Identity | B13: Gender | E13: 0/1 gender selector used by animation/equipment rules. | F13: 0 | G13: =IF(OR(B13="NpcTemplateID",C13=""),"",IF(B13="spell"," spell"&REPT(" ",MAX(1,24-LEN("spell")))&C13,IF(LEFT(B13,6)="CProp."," CProp"&REPT(" ",MAX(1,24-LEN("CProp")))&MID(B13,7,200)&REPT(" ",MAX(1,24-LEN(MID(B13,7,200))))&C13," "&B13&REPT(" ",MAX(1,24-LEN(B13)))&C13))) | H13: =IF($G16="","",$G16)
A14: Identity | B14: Equip | E14: Equipment template applied on spawn. | F14: dragon | G14: =IF(OR(B14="NpcTemplateID",C14=""),"",IF(B14="spell"," spell"&REPT(" ",MAX(1,24-LEN("spell")))&C14,IF(LEFT(B14,6)="CProp."," CProp"&REPT(" ",MAX(1,24-LEN("CProp")))&MID(B14,7,200)&REPT(" ",MAX(1,24-LEN(MID(B14,7,200))))&C14," "&B14&REPT(" ",MAX(1,24-LEN(B14)))&C14))) | H14: =IF($G17="","",$G17)
A15: Primary Stats + Scaling | B15: STR | E15: Base strength stat. If HITS is blank and CustomHitsLevel is not set, HP often ends up tracking strength after BaseStrmod is applied. | F15: 400 | G15: =IF(OR(B15="NpcTemplateID",C15=""),"",IF(B15="spell"," spell"&REPT(" ",MAX(1,24-LEN("spell")))&C15,IF(LEFT(B15,6)="CProp."," CProp"&REPT(" ",MAX(1,24-LEN("CProp")))&MID(B15,7,200)&REPT(" ",MAX(1,24-LEN(MID(B15,7,200))))&C15," "&B15&REPT(" ",MAX(1,24-LEN(B15)))&C15))) | H15: =IF(#REF!="","",#REF!) -> #REF!
A16: Primary Stats + Scaling | B16: INT | E16: Base intelligence stat. | F16: 200 | G16: =IF(OR(B16="NpcTemplateID",C16=""),"",IF(B16="spell"," spell"&REPT(" ",MAX(1,24-LEN("spell")))&C16,IF(LEFT(B16,6)="CProp."," CProp"&REPT(" ",MAX(1,24-LEN("CProp")))&MID(B16,7,200)&REPT(" ",MAX(1,24-LEN(MID(B16,7,200))))&C16," "&B16&REPT(" ",MAX(1,24-LEN(B16)))&C16))) | H16: =IF($G18="","",$G18)
A17: Primary Stats + Scaling | B17: DEX | E17: Base dexterity stat. | F17: 120 | G17: =IF(OR(B17="NpcTemplateID",C17=""),"",IF(B17="spell"," spell"&REPT(" ",MAX(1,24-LEN("spell")))&C17,IF(LEFT(B17,6)="CProp."," CProp"&REPT(" ",MAX(1,24-LEN("CProp")))&MID(B17,7,200)&REPT(" ",MAX(1,24-LEN(MID(B17,7,200))))&C17," "&B17&REPT(" ",MAX(1,24-LEN(B17)))&C17))) | H17: =IF($G19="","",$G19)
A18: Primary Stats + Scaling | B18: MANA | E18: Base mana pool. | F18: 200 | G18: =IF(OR(B18="NpcTemplateID",C18=""),"",IF(B18="spell"," spell"&REPT(" ",MAX(1,24-LEN("spell")))&C18,IF(LEFT(B18,6)="CProp."," CProp"&REPT(" ",MAX(1,24-LEN("CProp")))&MID(B18,7,200)&REPT(" ",MAX(1,24-LEN(MID(B18,7,200))))&C18," "&B18&REPT(" ",MAX(1,24-LEN(B18)))&C18))) | H18: =IF($G21="","",$G21)
A19: Primary Stats + Scaling | B19: STAM | E19: Base stamina pool. | F19: 120 | G19: =IF(OR(B19="NpcTemplateID",C19=""),"",IF(B19="spell"," spell"&REPT(" ",MAX(1,24-LEN("spell")))&C19,IF(LEFT(B19,6)="CProp."," CProp"&REPT(" ",MAX(1,24-LEN("CProp")))&MID(B19,7,200)&REPT(" ",MAX(1,24-LEN(MID(B19,7,200))))&C19," "&B19&REPT(" ",MAX(1,24-LEN(B19)))&C19))) | H19: =IF($G22="","",$G22)
A20: Primary Stats + Scaling | B20: CProp.BaseStrmod | E20: Strength modifier applied after base STR. This usually raises derived HP if HP is strength-based. | F20: i1000 | G20: =IF(OR(B20="NpcTemplateID",C20=""),"",IF(B20="spell"," spell"&REPT(" ",MAX(1,24-LEN("spell")))&C20,IF(LEFT(B20,6)="CProp."," CProp"&REPT(" ",MAX(1,24-LEN("CProp")))&MID(B20,7,200)&REPT(" ",MAX(1,24-LEN(MID(B20,7,200))))&C20," "&B20&REPT(" ",MAX(1,24-LEN(B20)))&C20))) | H20: =IF($G23="","",$G23)
A21: Primary Stats + Scaling | B21: CProp.BaseIntmod | E21: Additional intelligence modifier from custom property. | F21: i500 | G21: =IF(OR(B21="NpcTemplateID",C21=""),"",IF(B21="spell"," spell"&REPT(" ",MAX(1,24-LEN("spell")))&C21,IF(LEFT(B21,6)="CProp."," CProp"&REPT(" ",MAX(1,24-LEN("CProp")))&MID(B21,7,200)&REPT(" ",MAX(1,24-LEN(MID(B21,7,200))))&C21," "&B21&REPT(" ",MAX(1,24-LEN(B21)))&C21))) | H21: =IF($G24="","",$G24)
A22: Primary Stats + Scaling | B22: CProp.BaseDexmod | E22: Additional dexterity modifier from custom property. | F22: i100 | G22: =IF(OR(B22="NpcTemplateID",C22=""),"",IF(B22="spell"," spell"&REPT(" ",MAX(1,24-LEN("spell")))&C22,IF(LEFT(B22,6)="CProp."," CProp"&REPT(" ",MAX(1,24-LEN("CProp")))&MID(B22,7,200)&REPT(" ",MAX(1,24-LEN(MID(B22,7,200))))&C22," "&B22&REPT(" ",MAX(1,24-LEN(B22)))&C22))) | H22: =IF($G25="","",$G25)
A23: Primary Stats + Scaling | B23: CProp.CustomHitsLevel | E23: Custom HP override used by shard scripts. Common shard convention stores HP in hundredths, so i30000 becomes 300 HP. | G23: =IF(OR(B23="NpcTemplateID",C23=""),"",IF(B23="spell"," spell"&REPT(" ",MAX(1,24-LEN("spell")))&C23,IF(LEFT(B23,6)="CProp."," CProp"&REPT(" ",MAX(1,24-LEN("CProp")))&MID(B23,7,200)&REPT(" ",MAX(1,24-LEN(MID(B23,7,200))))&C23," "&B23&REPT(" ",MAX(1,24-LEN(B23)))&C23))) | H23: =IF($G26="","",$G26)
A24: Primary Stats + Scaling | B24: CProp.BaseHpRegen | E24: Passive HP regeneration modifier. | G24: =IF(OR(B24="NpcTemplateID",C24=""),"",IF(B24="spell"," spell"&REPT(" ",MAX(1,24-LEN("spell")))&C24,IF(LEFT(B24,6)="CProp."," CProp"&REPT(" ",MAX(1,24-LEN("CProp")))&MID(B24,7,200)&REPT(" ",MAX(1,24-LEN(MID(B24,7,200))))&C24," "&B24&REPT(" ",MAX(1,24-LEN(B24)))&C24))) | H24: =IF($G27="","",$G27)
A25: Primary Stats + Scaling | B25: CProp.BaseManaRegen | E25: Passive mana regeneration modifier. | G25: =IF(OR(B25="NpcTemplateID",C25=""),"",IF(B25="spell"," spell"&REPT(" ",MAX(1,24-LEN("spell")))&C25,IF(LEFT(B25,6)="CProp."," CProp"&REPT(" ",MAX(1,24-LEN("CProp")))&MID(B25,7,200)&REPT(" ",MAX(1,24-LEN(MID(B25,7,200))))&C25," "&B25&REPT(" ",MAX(1,24-LEN(B25)))&C25))) | H25: =IF($G28="","",$G28)
A26: Combat | B26: AttackAttribute | E26: Attack profile label. Kept mainly for staff/Seer info display; shard scripts do not use it to drive combat logic. | G26: =IF(OR(B26="NpcTemplateID",C26=""),"",IF(B26="spell"," spell"&REPT(" ",MAX(1,24-LEN("spell")))&C26,IF(LEFT(B26,6)="CProp."," CProp"&REPT(" ",MAX(1,24-LEN("CProp")))&MID(B26,7,200)&REPT(" ",MAX(1,24-LEN(MID(B26,7,200))))&C26," "&B26&REPT(" ",MAX(1,24-LEN(B26)))&C26))) | H26: =IF($G29="","",$G29)
A27: Combat | B27: AttackSpeed | E27: Attack speed note field. Kept for template documentation/display; shard scripts do not read this value for combat behavior. | G27: =IF(OR(B27="NpcTemplateID",C27=""),"",IF(B27="spell"," spell"&REPT(" ",MAX(1,24-LEN("spell")))&C27,IF(LEFT(B27,6)="CProp."," CProp"&REPT(" ",MAX(1,24-LEN("CProp")))&MID(B27,7,200)&REPT(" ",MAX(1,24-LEN(MID(B27,7,200))))&C27," "&B27&REPT(" ",MAX(1,24-LEN(B27)))&C27))) | H27: =IF($G30="","",$G30)
A28: Combat | B28: AttackDamage | E28: Attack damage note field. Kept mainly for staff/Seer info display rather than live combat calculation. | G28: =IF(OR(B28="NpcTemplateID",C28=""),"",IF(B28="spell"," spell"&REPT(" ",MAX(1,24-LEN("spell")))&C28,IF(LEFT(B28,6)="CProp."," CProp"&REPT(" ",MAX(1,24-LEN("CProp")))&MID(B28,7,200)&REPT(" ",MAX(1,24-LEN(MID(B28,7,200))))&C28," "&B28&REPT(" ",MAX(1,24-LEN(B28)))&C28))) | H28: =IF($G31="","",$G31)
A29: Combat | B29: AR | E29: Armor rating baseline. | G29: =IF(OR(B29="NpcTemplateID",C29=""),"",IF(B29="spell"," spell"&REPT(" ",MAX(1,24-LEN("spell")))&C29,IF(LEFT(B29,6)="CProp."," CProp"&REPT(" ",MAX(1,24-LEN("CProp")))&MID(B29,7,200)&REPT(" ",MAX(1,24-LEN(MID(B29,7,200))))&C29," "&B29&REPT(" ",MAX(1,24-LEN(B29)))&C29))) | H29: =IF($G32="","",$G32)
A30: Behavior/Faction | B30: alignment | E30: Behavior allegiance (for example good/evil). | F30: evil | G30: =IF(OR(B30="NpcTemplateID",C30=""),"",IF(B30="spell"," spell"&REPT(" ",MAX(1,24-LEN("spell")))&C30,IF(LEFT(B30,6)="CProp."," CProp"&REPT(" ",MAX(1,24-LEN("CProp")))&MID(B30,7,200)&REPT(" ",MAX(1,24-LEN(MID(B30,7,200))))&C30," "&B30&REPT(" ",MAX(1,24-LEN(B30)))&C30))) | H30: =IF($G33="","",$G33)
A31: Behavior/Faction | B31: hostile | E31: If set, NPC auto-hostiles players/targets. | F31: 1 | G31: =IF(OR(B31="NpcTemplateID",C31=""),"",IF(B31="spell"," spell"&REPT(" ",MAX(1,24-LEN("spell")))&C31,IF(LEFT(B31,6)="CProp."," CProp"&REPT(" ",MAX(1,24-LEN("CProp")))&MID(B31,7,200)&REPT(" ",MAX(1,24-LEN(MID(B31,7,200))))&C31," "&B31&REPT(" ",MAX(1,24-LEN(B31)))&C31))) | H31: =IF($G34="","",$G34)
A32: Behavior/Faction | B32: virtue | E32: Virtue/karma subsystem bucket value used by shard scripts. | F32: 8 | G32: =IF(OR(B32="NpcTemplateID",C32=""),"",IF(B32="spell"," spell"&REPT(" ",MAX(1,24-LEN("spell")))&C32,IF(LEFT(B32,6)="CProp."," CProp"&REPT(" ",MAX(1,24-LEN("CProp")))&MID(B32,7,200)&REPT(" ",MAX(1,24-LEN(MID(B32,7,200))))&C32," "&B32&REPT(" ",MAX(1,24-LEN(B32)))&C32))) | H32: =IF($G35="","",$G35)
A33: Behavior/Faction | B33: Karma | E33: Karma value used for notoriety/kill rewards. | F33: -10000 | G33: =IF(OR(B33="NpcTemplateID",C33=""),"",IF(B33="spell"," spell"&REPT(" ",MAX(1,24-LEN("spell")))&C33,IF(LEFT(B33,6)="CProp."," CProp"&REPT(" ",MAX(1,24-LEN("CProp")))&MID(B33,7,200)&REPT(" ",MAX(1,24-LEN(MID(B33,7,200))))&C33," "&B33&REPT(" ",MAX(1,24-LEN(B33)))&C33))) | H33: =IF($G36="","",$G36)
A34: Behavior/Faction | B34: Fame | E34: Fame value used for notoriety/kill rewards. | F34: 10000 | G34: =IF(OR(B34="NpcTemplateID",C34=""),"",IF(B34="spell"," spell"&REPT(" ",MAX(1,24-LEN("spell")))&C34,IF(LEFT(B34,6)="CProp."," CProp"&REPT(" ",MAX(1,24-LEN("CProp")))&MID(B34,7,200)&REPT(" ",MAX(1,24-LEN(MID(B34,7,200))))&C34," "&B34&REPT(" ",MAX(1,24-LEN(B34)))&C34))) | H34: =IF($G37="","",$G37)
A35: Behavior/Faction | B35: guardignore | E35: If set, guards ignore this NPC. | G35: =IF(OR(B35="NpcTemplateID",C35=""),"",IF(B35="spell"," spell"&REPT(" ",MAX(1,24-LEN("spell")))&C35,IF(LEFT(B35,6)="CProp."," CProp"&REPT(" ",MAX(1,24-LEN("CProp")))&MID(B35,7,200)&REPT(" ",MAX(1,24-LEN(MID(B35,7,200))))&C35," "&B35&REPT(" ",MAX(1,24-LEN(B35)))&C35))) | H35: =IF($G38="","",$G38)
A36: Behavior/Faction | B36: dstart | E36: AI perception/engagement start distance. | G36: =IF(OR(B36="NpcTemplateID",C36=""),"",IF(B36="spell"," spell"&REPT(" ",MAX(1,24-LEN("spell")))&C36,IF(LEFT(B36,6)="CProp."," CProp"&REPT(" ",MAX(1,24-LEN("CProp")))&MID(B36,7,200)&REPT(" ",MAX(1,24-LEN(MID(B36,7,200))))&C36," "&B36&REPT(" ",MAX(1,24-LEN(B36)))&C36))) | H36: =IF($G39="","",$G39)
A37: Behavior/Faction | B37: speech | E37: Speech profile/group index. | G37: =IF(OR(B37="NpcTemplateID",C37=""),"",IF(B37="spell"," spell"&REPT(" ",MAX(1,24-LEN("spell")))&C37,IF(LEFT(B37,6)="CProp."," CProp"&REPT(" ",MAX(1,24-LEN("CProp")))&MID(B37,7,200)&REPT(" ",MAX(1,24-LEN(MID(B37,7,200))))&C37," "&B37&REPT(" ",MAX(1,24-LEN(B37)))&C37))) | H37: =IF($G40="","",$G40)
A38: Behavior/Faction | B38: saywords | E38: Enables NPC speech lines during behavior. | G38: =IF(OR(B38="NpcTemplateID",C38=""),"",IF(B38="spell"," spell"&REPT(" ",MAX(1,24-LEN("spell")))&C38,IF(LEFT(B38,6)="CProp."," CProp"&REPT(" ",MAX(1,24-LEN("CProp")))&MID(B38,7,200)&REPT(" ",MAX(1,24-LEN(MID(B38,7,200))))&C38," "&B38&REPT(" ",MAX(1,24-LEN(B38)))&C38))) | H38: =IF($G41="","",$G41)
A39: Loot | B39: lootgroup | E39: Loot table group ID. | F39: 133 | G39: =IF(OR(B39="NpcTemplateID",C39=""),"",IF(B39="spell"," spell"&REPT(" ",MAX(1,24-LEN("spell")))&C39,IF(LEFT(B39,6)="CProp."," CProp"&REPT(" ",MAX(1,24-LEN("CProp")))&MID(B39,7,200)&REPT(" ",MAX(1,24-LEN(MID(B39,7,200))))&C39," "&B39&REPT(" ",MAX(1,24-LEN(B39)))&C39))) | H39: =IF($G42="","",$G42)
A40: Loot | B40: MagicItemChance | E40: Chance percent for magic drop rolls. | F40: 90 | G40: =IF(OR(B40="NpcTemplateID",C40=""),"",IF(B40="spell"," spell"&REPT(" ",MAX(1,24-LEN("spell")))&C40,IF(LEFT(B40,6)="CProp."," CProp"&REPT(" ",MAX(1,24-LEN("CProp")))&MID(B40,7,200)&REPT(" ",MAX(1,24-LEN(MID(B40,7,200))))&C40," "&B40&REPT(" ",MAX(1,24-LEN(B40)))&C40))) | H40: =IF($G43="","",$G43)
...

Sheet FieldDictionary
A1: Variable | B1: Type | C1: Description | D1: Observed Count | E1: Preferred Case
A2: Stats+Scaling precedence | B2: Note | C2: STR is the base stat, HITS is a direct hp assignment, BaseStrmod is an extra strength modifier, and CustomHitsLevel is the shard's hp override (commonly stored in hundredths, so i30000 becomes 300 hp).
A3: Name | B3: TopLevel | C3: Display name for NPC; can use <random> tokens where supported. | D3: 750 | E3: Name
A4: script | B4: TopLevel | C4: AI/behavior script attached to NPC. | D4: 750 | E4: script
A5: objtype | B5: TopLevel | C5: Body/object type ID (hex or decimal). | D5: 750 | E5: objtype
A6: Color | B6: TopLevel | C6: Hue override for body/equipment visuals. | D6: 750 | E6: Color
A7: TrueColor | B7: TopLevel | C7: Permanent hue that should persist through updates. | D7: 750 | E7: TrueColor
A8: Gender | B8: TopLevel | C8: 0/1 gender selector used by animation/equipment rules. | D8: 750 | E8: Gender
A9: STR | B9: TopLevel | C9: Base strength stat. If HITS is blank and CustomHitsLevel is not set, HP often ends up tracking strength after BaseStrmod is applied. | D9: 750 | E9: STR
A10: INT | B10: TopLevel | C10: Base intelligence stat. | D10: 750 | E10: INT
A11: DEX | B11: TopLevel | C11: Base dexterity stat. | D11: 750 | E11: DEX
A12: begging | B12: TopLevel | C12: Top-level NPC template field. | D12: 1 | E12: begging
A13: bowcraft | B13: TopLevel | C13: Top-level NPC template field. | D13: 1 | E13: bowcraft
A14: itemid | B14: TopLevel | C14: Top-level NPC template field. | D14: 1 | E14: itemid
... A168: NpcTemplateID | B168: BuilderOnly | C168: Builder-only template id written after NpcTemplate. Use letters/numbers and no spaces. | D168: 1 | E168: NpcTemplateID

Sheet Output
A1: NpcTemplate Output
A2: ="NpcTemplate "&SUBSTITUTE(TRIM(Builder!C7)," ","") -> NpcTemplate
A3: {
A4: =IF(Builder!$G7="","",Builder!$G7)
A5: =IF(Builder!$G8="","",Builder!$G8)
A6: =IF(Builder!$G9="","",Builder!$G9)
A7: =IF(Builder!$G10="","",Builder!$G10)
A8: =IF(Builder!$G11="","",Builder!$G11)
A9: =IF(Builder!$G12="","",Builder!$G12)
A10: =IF(Builder!$G13="","",Builder!$G13)
A11: =IF(Builder!$G14="","",Builder!$G14)
A12: =IF(Builder!$G15="","",Builder!$G15)
A13: =IF(Builder!$G16="","",Builder!$G16)
A14: =IF(Builder!$G17="","",Builder!$G17)
A15: =IF(Builder!#REF!="","",Builder!#REF!) -> #REF!
A16: =IF(Builder!$G18="","",Builder!$G18)
A17: =IF(Builder!$G19="","",Builder!$G19)
A18: =IF(Builder!$G20="","",Builder!$G20)
A19: =IF(Builder!$G21="","",Builder!$G21)
A20: =IF(Builder!$G22="","",Builder!$G22)
A21: =IF(Builder!$G23="","",Builder!$G23)
A22: =IF(Builder!$G24="","",Builder!$G24)
A23: =IF(Builder!$G25="","",Builder!$G25)
A24: =IF(Builder!$G26="","",Builder!$G26)
A25: =IF(Builder!$G27="","",Builder!$G27)
A26: =IF(Builder!$G28="","",Builder!$G28)
A27: =IF(Builder!$G29="","",Builder!$G29)
... A1003: =IF(Builder!$G1005="","",Builder!$G1005)
A1004: }

Sheet SpellLists
A1: Spell | B1: InNpcdesc | C1: UseCountInNpcdesc
A2: abyssalflame | B2: yes | C2: 66
A3: agility | B3: no | C3: 0
A4: angelicaura | B4: yes | C4: 4
A5: angelicfeast | B5: no | C5: 0
A6: angelicgate | B6: no | C6: 0
A7: animatedead | B7: no | C7: 0
A8: antidote | B8: no | C8: 0
A9: apocalypse | B9: yes | C9: 4
A10: archcure | B10: no | C10: 0
A11: archprot | B11: no | C11: 0
A12: astralstorm | B12: yes | C12: 9
A13: blade_spirit | B13: yes | C13: 6
... A154: wyvernstrike | B154: yes | C154: 55

Sheet SkillLists
A1: Skill
A2: begging
A3: bowcraft
A4: itemid
A5: tailoring
A6: Parry
A7: Tactics
A8: Inscription
A9: lumberjacking
A10: tinkering
A11: fishing
A12: Poisoning
... A63: Prop

Sheet AllVariables
A1: Variable | B1: Category | C1: ObservedCount | D1: MeanOrderInTemplate | E1: PreferredCase
A2: Name | B2: TopLevel | C2: 750 | D2: 0 | E2: Name
A3: script | B3: TopLevel | C3: 750 | D3: 1 | E3: script
A4: objtype | B4: TopLevel | C4: 750 | D4: 2.01 | E4: objtype
A5: Color | B5: TopLevel | C5: 750 | D5: 3.01 | E5: Color
A6: TrueColor | B6: TopLevel | C6: 750 | D6: 4.01 | E6: TrueColor
A7: Gender | B7: TopLevel | C7: 750 | D7: 5.02 | E7: Gender
A8: STR | B8: TopLevel | C8: 750 | D8: 6.15 | E8: STR
A9: INT | B9: TopLevel | C9: 750 | D9: 7.16 | E9: INT
A10: DEX | B10: TopLevel | C10: 750 | D10: 8.13 | E10: DEX
A11: begging | B11: TopLevel | C11: 1 | D11: 9 | E11: begging
A12: bowcraft | B12: TopLevel | C12: 1 | D12: 9 | E12: bowcraft
A13: itemid | B13: TopLevel | C13: 1 | D13: 9 | E13: itemid
... A164: CProp.kappa | B164: CProp | C164: 1 | D164: 87 | E164: kappa
